Workbook
Name TABLA_REV: [1]!Tabla2[#All]

Sheet Resumen Ejecutivo
B1: RC | C1: Control Maestro · Reforma Curricular | O1: 📅 13 marzo 2026 | P1: Todas las facultades
P2: Facultad de Sociedad, Cultura y Creatividad
B3: 🔽 FILTRAR | C3: Híbrido | E3: Facultad de Negocios, Gestión y Sostenibilidad | H3: Todos los periodos | I3: ✕ Limpiar: seleccione 'Todas las...' en cada filtro | M3: {=CONCATENATE("Mostrando ",TEXT(SUMPRODUCT(((('Resumen Ejecutivo'!C3="Todas las modalidades")+(Maestro!F11:F70='Resumen Ejecutivo'!C3)>0)*(('Resumen Ejecutivo'!E3="Todas las facultades")+(Maestro!C11:C70='Resumen Ejecutivo'!E3)>0)*(('Resumen Ejecutivo'!H3="Todos los periodos")+(Maestro!BV11:BV70='Resumen Ejecutivo'!H3)>0))),"0")," de 60 programas")} -> Mostrando 0 de 60 programas | P3: Facultad de Ingeniería, Diseño e Innovación
P4: Facultad de Negocios, Gestión y Sostenibilidad
P6: Todos los periodos
B7: RESUMEN GENERAL | D7: Vicerrectoría Académica — Etapas según hoja Estructura | P7: Ya está en oferta
P8: 2026-2
B9: {=SUMPRODUCT(((('Resumen Ejecutivo'!C3="Todas las modalidades")+(Maestro!F11:F70='Resumen Ejecutivo'!C3)>0)*(('Resumen Ejecutivo'!E3="Todas las facultades")+(Maestro!C11:C70='Resumen Ejecutivo'!E3)>0)*(('Resumen Ejecutivo'!H3="Todos los periodos")+(Maestro!BV11:BV70='Resumen Ejecutivo'!H3)>0)))} -> 0 | D9: {=(IFERROR(ROUND(SUMPRODUCT(((('Resumen Ejecutivo'!C3="Todas las modalidades")+(Maestro!F11:F70='Resumen Ejecutivo'!C3)>0)*(('Resumen Ejecutivo'!E3="Todas las facultades")+(Maestro!C11:C70='Resumen Ejecutivo'!E3)>0)*(('Resumen Ejecutivo'!H3="Todos los periodos")+(Maestro!BV11:BV70='Resumen Ejecutivo'!H3)>0))*((ISNUMBER(SEARCH("finalizado",Maestro!J11:J70))*1)+(ISNUMBER(SEARCH("finalizado",Maestro!Y11:Y70))*1)+((ISNUMBER(SEARCH("finalizado",Maestro!AB11:AB70))+ISNUMBER(SEARCH("resolución",Maestro!AB11:AB70))+ISNUMBER(SEARCH("aprobado",Maestro!AB11:AB70))+ISNUMBER(SEARCH("notificado",Maestro!AB11:AB70))>0)*1)+((NOT(ISNUMBER(SEARCH("sin iniciar",Maestro!AI11:AI70)))*NOT(ISNUMBER(SEARCH("no aplica",Maestro!AI11:AI70)))*(Maestro!AI11:AI70<>""))*1)+((ISNUMBER(Maestro!AQ11:AQ70)*(Maestro!AQ11:AQ70>=1)))+((ISNUMBER(Maestro!AZ11:AZ70)*(Maestro!AZ11:AZ70>=1)))+((ISNUMBER(Maestro!BG11:BG70)*(Maestro!BG11:BG70>=1)))+((ISNUMBER(Maestro!BL11:BL70)*(Maestro!BL11:BL70>=1)))+(ISNUMBER(SEARCH("en proceso",Maestro!J11:J70))*1)*0.5+(ISNUMBER(SEARCH("en proceso",Maestro!Y11:Y70))*1)*0.5+((ISNUMBER(SEARCH("evaluación",Maestro!AB11:AB70))+ISNUMBER(SEARCH("elaboración",Maestro!AB11:AB70))+ISNUMBER(SEARCH("pares",Maestro!AB11:AB70))>0)*1)*0.5+(0)*0.5+((ISNUMBER(Maestro!AQ11:AQ70)*(Maestro!AQ11:AQ70>0)*(Maestro!AQ11:AQ70<1)))*0.5+((ISNUMBER(Maestro!AZ11:AZ70)*(Maestro!AZ11:AZ70>0)*(Maestro!AZ11:AZ70<1)))*0.5+((ISNUMBER(Maestro!BG11:BG70)*(Maestro!BG11:BG70>0)*(Maestro!BG11:BG70<1)))*0.5+((ISNUMBER(Maestro!BL11:BL70)*(Maestro!BL11:BL70>0)*(Maestro!BL11:BL70<1)))*0.5))/(SUMPRODUCT(((('Resumen Ejecutivo'!C3="Todas las modalidades")+(Maestro!F11:F70='Resumen Ejecutivo'!C3)>0)*(('Resumen Ejecutivo'!E3="Todas las facultades")+(Maestro!C11:C70='Resumen Ejecutivo'!E3)>0)*(('Resumen Ejecutivo'!H3="Todos los periodos")+(Maestro!BV11:BV70='Resumen Ejecutivo'!H3)>0)))*8)*100,0),0)&"%")} -> 0% | F9: {=IFERROR(SUMPRODUCT(((('Resumen Ejecutivo'!C3="Todas las modalidades")+(Maestro!F11:F70='Resumen Ejecutivo'!C3)>0)*(('Resumen Ejecutivo'!E3="Todas las facultades")+(Maestro!C11:C70='Resumen Ejecutivo'!E3)>0)*(('Resumen Ejecutivo'!H3="Todos los periodos")+(Maestro!BV11:BV70='Resumen Ejecutivo'!H3)>0))*((ISNUMBER(SEARCH("finalizado",Maestro!J11:J70))*1+ISNUMBER(SEARCH("no aplica",Maestro!J11:J70))*1)+(ISNUMBER(SEARCH("finalizado",Maestro!Y11:Y70))*1+ISNUMBER(SEARCH("no aplica",Maestro!Y11:Y70))*1)+((ISNUMBER(SEARCH("finalizado",Maestro!AB11:AB70))+ISNUMBER(SEARCH("resolución",Maestro!AB11:AB70))+ISNUMBER(SEARCH("aprobado",Maestro!AB11:AB70))+ISNUMBER(SEARCH("notificado",Maestro!AB11:AB70))>0)*1+ISNUMBER(SEARCH("no aplica",Maestro!AB11:AB70))*1)+((NOT(ISNUMBER(SEARCH("sin iniciar",Maestro!AI11:AI70)))*NOT(ISNUMBER(SEARCH("no aplica",Maestro!AI11:AI70)))*(Maestro!AI11:AI70<>""))*1+ISNUMBER(SEARCH("no aplica",Maestro!AI11:AI70))*1)+((ISNUMBER(Maestro!AQ11:AQ70)*(Maestro!AQ11:AQ70>=1))+ISNUMBER(SEARCH("no aplica",Maestro!AQ11:AQ70))*1)+((ISNUMBER(Maestro!AZ11:AZ70)*(Maestro!AZ11:AZ70>=1))+ISNUMBER(SEARCH("no aplica",Maestro!AZ11:AZ70))*1)+((ISNUMBER(Maestro!BG11:BG70)*(Maestro!BG11:BG70>=1))+ISNUMBER(SEARCH("no aplica",Maestro!BG11:BG70))*1)+((ISNUMBER(Maestro!BL11:BL70)*(Maestro!BL11:BL70>=1))+ISNUMBER(SEARCH("no aplica",Maestro!BL11:BL70))*1))),0)} -> 0 | H9: {=IFERROR(SUMPRODUCT(((('Resumen Ejecutivo'!C3="Todas las modalidades")+(Maestro!F11:F70='Resumen Ejecutivo'!C3)>0)*(('Resumen Ejecutivo'!E3="Todas las facultades")+(Maestro!C11:C70='Resumen Ejecutivo'!E3)>0)*(('Resumen Ejecutivo'!H3="Todos los periodos")+(Maestro!BV11:BV70='Resumen Ejecutivo'!H3)>0))*((ISNUMBER(SEARCH("en proceso",Maestro!J11:J70))*1)+(ISNUMBER(SEARCH("en proceso",Maestro!Y11:Y70))*1)+((ISNUMBER(SEARCH("evaluación",Maestro!AB11:AB70))+ISNUMBER(SEARCH("elaboración",Maestro!AB11:AB70))+ISNUMBER(SEARCH("pares",Maestro!AB11:AB70))>0)*1)+(0)+((ISNUMBER(Maestro!AQ11:AQ70)*(Maestro!AQ11:AQ70>0)*(Maestro!AQ11:AQ70<1)))+((ISNUMBER(Maestro!AZ11:AZ70)*(Maestro!AZ11:AZ70>0)*(Maestro!AZ11:AZ70<1)))+((ISNUMBER(Maestro!BG11:BG70)*(Maestro!BG11:BG70>0)*(Maestro!BG11:BG70<1)))+((ISNUMBER(Maestro!BL11:BL70)*(Maestro!BL11:BL70>0)*(Maestro!BL11:BL70<1))))),0)} -> 0 | J9: {=IFERROR(SUMPRODUCT(((('Resumen Ejecutivo'!C3="Todas las modalidades")+(Maestro!F11:F70='Resumen Ejecutivo'!C3)>0)*(('Resumen Ejecutivo'!E3="Todas las facultades")+(Maestro!C11:C70='Resumen Ejecutivo'!E3)>0)*(('Resumen Ejecutivo'!H3="Todos los periodos")+(Maestro!BV11:BV70='Resumen Ejecutivo'!H3)>0)))*8-SUMPRODUCT(((('Resumen Ejecutivo'!C3="Todas las modalidades")+(Maestro!F11:F70='Resumen Ejecutivo'!C3)>0)*(('Resumen Ejecutivo'!E3="Todas las facultades")+(Maestro!C11:C70='Resumen Ejecutivo'!E3)>0)*(('Resumen Ejecutivo'!H3="Todos los periodos")+(Maestro!BV11:BV70='Resumen Ejecutivo'!H3)>0))*((ISNUMBER(SEARCH("finalizado",Maestro!J11:J70))*1+ISNUMBER(SEARCH("no aplica",Maestro!J11:J70))*1)+(ISNUMBER(SEARCH("finalizado",Maestro!Y11:Y70))*1+ISNUMBER(SEARCH("no aplica",Maestro!Y11:Y70))*1)+((ISNUMBER(SEARCH("finalizado",Maestro!AB11:AB70))+ISNUMBER(SEARCH("resolución",Maestro!AB11:AB70))+ISNUMBER(SEARCH("aprobado",Maestro!AB11:AB70))+ISNUMBER(SEARCH("notificado",Maestro!AB11:AB70))>0)*1+ISNUMBER(SEARCH("no aplica",Maestro!AB11:AB70))*1)+((NOT(ISNUMBER(SEARCH("sin iniciar",Maestro!AI11:AI70)))*NOT(ISNUMBER(SEARCH("no aplica",Maestro!AI11:AI70)))*(Maestro!AI11:AI70<>""))*1+ISNUMBER(SEARCH("no aplica",Maestro!AI11:AI70))*1)+((ISNUMBER(Maestro!AQ11:AQ70)*(Maestro!AQ11:AQ70>=1))+ISNUMBER(SEARCH("no aplica",Maestro!AQ11:AQ70))*1)+((ISNUMBER(Maestro!AZ11:AZ70)*(Maestro!AZ11:AZ70>=1))+ISNUMBER(SEARCH("no aplica",Maestro!AZ11:AZ70))*1)+((ISNUMBER(Maestro!BG11:BG70)*(Maestro!BG11:BG70>=1))+ISNUMBER(SEARCH("no aplica",Maestro!BG11:BG70))*1)+((ISNUMBER(Maestro!BL11:BL70)*(Maestro!BL11:BL70>=1))+ISNUMBER(SEARCH("no aplica",Maestro!BL11:BL70))*1)))-SUMPRODUCT(((('Resumen Ejecutivo'!C3="Todas las modalidades")+(Maestro!F11:F70='Resumen Ejecutivo'!C3)>0)*(('Resumen Ejecutivo'!E3="Todas las facultades")+(Maestro!C11:C70='Resumen Ejecutivo'!E3)>0)*(('Resumen Ejecutivo'!H3="Todos los periodos")+(Maestro!BV11:BV70='Resumen Ejecutivo'!H3)>0))*((ISNUMBER(SEARCH("en proceso",Maestro!J11:J70))*1)+(ISNUMBER(SEARCH("en proceso",Maestro!Y11:Y70))*1)+((ISNUMBER(SEARCH("evaluación",Maestro!AB11:AB70))+ISNUMBER(SEARCH("elaboración",Maestro!AB11:AB70))+ISNUMBER(SEARCH("pares",Maestro!AB11:AB70))>0)*1)+(0)+((ISNUMBER(Maestro!AQ11:AQ70)*(Maestro!AQ11:AQ70>0)*(Maestro!AQ11:AQ70<1)))+((ISNUMBER(Maestro!AZ11:AZ70)*(Maestro!AZ11:AZ70>0)*(Maestro!AZ11:AZ70<1)))+((ISNUMBER(Maestro!BG11:BG70)*(Maestro!BG11:BG70>0)*(Maestro!BG11:BG70<1)))+((ISNUMBER(Maestro!BL11:BL70)*(Maestro!BL11:BL70>0)*(Maestro!BL11:BL70<1))))),0)} -> 0 | L9: {=IFERROR(SUMPRODUCT(((('Resumen Ejecutivo'!C3="Todas las modalidades")+(Maestro!F11:F70='Resumen Ejecutivo'!C3)>0)*(('Resumen Ejecutivo'!E3="Todas las facultades")+(Maestro!C11:C70='Resumen Ejecutivo'!E3)>0)*(('Resumen Ejecutivo'!H3="Todos los periodos")+(Maestro!BV11:BV70='Resumen Ejecutivo'!H3)>0))*(((ISNUMBER(SEARCH("finalizado",Maestro!J11:J70))*1)+(ISNUMBER(SEARCH("finalizado",Maestro!Y11:Y70))*1)+((ISNUMBER(SEARCH("finalizado",Maestro!AB11:AB70))+ISNUMBER(SEARCH("resolución",Maestro!AB11:AB70))+ISNUMBER(SEARCH("aprobado",Maestro!AB11:AB70))+ISNUMBER(SEARCH("notificado",Maestro!AB11:AB70))>0)*1)+((NOT(ISNUMBER(SEARCH("sin iniciar",Maestro!AI11:AI70)))*NOT(ISNUMBER(SEARCH("no aplica",Maestro!AI11:AI70)))*(Maestro!AI11:AI70<>""))*1)+((ISNUMBER(Maestro!AQ11:AQ70)*(Maestro!AQ11:AQ70>=1)))+((ISNUMBER(Maestro!AZ11:AZ70)*(Maestro!AZ11:AZ70>=1)))+((ISNUMBER(Maestro!BG11:BG70)*(Maestro!BG11:BG70>=1)))+((ISNUMBER(Maestro!BL11:BL70)*(Maestro!BL11:BL70>=1)))+(ISNUMBER(SEARCH("en proceso",Maestro!J11:J70))*1)*0.5+(ISNUMBER(SEARCH("en proceso",Maestro!Y11:Y70))*1)*0.5+((ISNUMBER(SEARCH("evaluación",Maestro!AB11:AB70))+ISNUMBER(SEARCH("elaboración",Maestro!AB11:AB70))+ISNUMBER(SEARCH("pares",Maestro!AB11:AB70))>0)*1)*0.5+(0)*0.5+((ISNUMBER(Maestro!AQ11:AQ70)*(Maestro!AQ11:AQ70>0)*(Maestro!AQ11:AQ70<1)))*0.5+((ISNUMBER(Maestro!AZ11:AZ70)*(Maestro!AZ11:AZ70>0)*(Maestro!AZ11:AZ70<1)))*0.5+((ISNUMBER(Maestro!BG11:BG70)*(Maestro!BG11:BG70>0)*(Maestro!BG11:BG70<1)))*0.5+((ISNUMBER(Maestro!BL11:BL70)*(Maestro!BL11:BL70>0)*(Maestro!BL11:BL70<1)))*0.5)<2.4)),0)} -> 0 | P9: 2027-1
P10: 2027-2
B13: AVANCE POR ETAPA — 8 procesos según hoja Estructura · 60 programas
B14: {=CONCATENATE("AVANCE POR ETAPA — 8 procesos según hoja Estructura · ",TEXT(SUMPRODUCT(((('Resumen Ejecutivo'!C3="Todas las modalidades")+(Maestro!F11:F70='Resumen Ejecutivo'!C3)>0)*(('Resumen Ejecutivo'!E3="Todas las facultades")+(Maestro!C11:C70='Resumen Ejecutivo'!E3)>0)*(('Resumen Ejecutivo'!H3="Todos los periodos")+(Maestro!BV11:BV70='Resumen Ejecutivo'!H3)>0))),"0")," programas")} -> AVANCE POR ETAPA — 8 procesos según hoja Estructura · 0 programas
B15: GESTIÓN ACADÉMICA | D15: {=IFERROR(ROUND((SUMPRODUCT(((('Resumen Ejecutivo'!C3="Todas las modalidades")+(Maestro!F11:F70='Resumen Ejecutivo'!C3)>0)*(('Resumen Ejecutivo'!E3="Todas las facultades")+(Maestro!C11:C70='Resumen Ejecutivo'!E3)>0)*(('Resumen Ejecutivo'!H3="Todos los periodos")+(Maestro!BV11:BV70='Resumen Ejecutivo'!H3)>0))*ISNUMBER(SEARCH("finalizado",Maestro!J11:J70))*1)+(SUMPRODUCT(((('Resumen Ejecutivo'!C3="Todas las modalidades")+(Maestro!F11:F70='Resumen Ejecutivo'!C3)>0)*(('Resumen Ejecutivo'!E3="Todas las facultades")+(Maestro!C11:C70='Resumen Ejecutivo'!E3)>0)*(('Resumen Ejecutivo'!H3="Todos los periodos")+(Maestro!BV11:BV70='Resumen Ejecutivo'!H3)>0))*ISNUMBER(SEARCH("en proceso",Maestro!J11:J70))*1))*0.5)/SUMPRODUCT(((('Resumen Ejecutivo'!C3="Todas las modalidades")+(Maestro!F11:F70='Resumen Ejecutivo'!C3)>0)*(('Resumen Ejecutivo'!E3="Todas las facultades")+(Maestro!C11:C70='Resumen Ejecutivo'!E3)>0)*(('Resumen Ejecutivo'!H3="Todos los periodos")+(Maestro!BV11:BV70='Resumen Ejecutivo'!H3)>0)))*100,0),0)} -> 0 | E15: GESTIÓN FINANCIERA | G15: {=IFERROR(ROUND((SUMPRODUCT(((('Resumen Ejecutivo'!C3="Todas las modalidades")+(Maestro!F11:F70='Resumen Ejecutivo'!C3)>0)*(('Resumen Ejecutivo'!E3="Todas las facultades")+(Maestro!C11:C70='Resumen Ejecutivo'!E3)>0)*(('Resumen Ejecutivo'!H3="Todos los periodos")+(Maestro!BV11:BV70='Resumen Ejecutivo'!H3)>0))*ISNUMBER(SEARCH("finalizado",Maestro!Y11:Y70))*1)+(SUMPRODUCT(((('Resumen Ejecutivo'!C3="Todas las modalidades")+(Maestro!F11:F70='Resumen Ejecutivo'!C3)>0)*(('Resumen Ejecutivo'!E3="Todas las facultades")+(Maestro!C11:C70='Resumen Ejecutivo'!E3)>0)*(('Resumen Ejecutivo'!H3="Todos los periodos")+(Maestro!BV11:BV70='Resumen Ejecutivo'!H3)>0))*ISNUMBER(SEARCH("en proceso",Maestro!Y11:Y70))*1))*0.5)/SUMPRODUCT(((('Resumen Ejecutivo'!C3="Todas las modalidades")+(Maestro!F11:F70='Resumen Ejecutivo'!C3)>0)*(('Resumen Ejecutivo'!E3="Todas las facultades")+(Maestro!C11:C70='Resumen Ejecutivo'!E3)>0)*(('Resumen Ejecutivo'!H3="Todos los periodos")+(Maestro!BV11:BV70='Resumen Ejecutivo'!H3)>0)))*100,0),0)} -> 0 | H15: ASEGURAMIENTO CALIDAD | J15: {=IFERROR(ROUND((SUMPRODUCT(((('Resumen Ejecutivo'!C3="Todas las modalidades")+(Maestro!F11:F70='Resumen Ejecutivo'!C3)>0)*(('Resumen Ejecutivo'!E3="Todas las facultades")+(Maestro!C11:C70='Resumen Ejecutivo'!E3)>0)*(('Resumen Ejecutivo'!H3="Todos los periodos")+(Maestro!BV11:BV70='Resumen Ejecutivo'!H3)>0))*(ISNUMBER(SEARCH("resolución",Maestro!AB11:AB70))+ISNUMBER(SEARCH("aprobado",Maestro!AB11:AB70))+ISNUMBER(SEARCH("notificado",Maestro!AB11:AB70))>0)*1)+(SUMPRODUCT(((('Resumen Ejecutivo'!C3="Todas las modalidades")+(Maestro!F11:F70='Resumen Ejecutivo'!C3)>0)*(('Resumen Ejecutivo'!E3="Todas las facultades")+(Maestro!C11:C70='Resumen Ejecutivo'!E3)>0)*(('Resumen Ejecutivo'!H3="Todos los periodos")+(Maestro!BV11:BV70='Resumen Ejecutivo'!H3)>0))*(ISNUMBER(SEARCH("evaluación",Maestro!AB11:AB70))+ISNUMBER(SEARCH("elaboración",Maestro!AB11:AB70))+ISNUMBER(SEARCH("pares",Maestro!AB11:AB70))+ISNUMBER(SEARCH("completitud",Maestro!AB11:AB70))>0)*1))*0.5)/SUMPRODUCT(((('Resumen Ejecutivo'!C3="Todas las modalidades")+(Maestro!F11:F70='Resumen Ejecutivo'!C3)>0)*(('Resumen Ejecutivo'!E3="Todas las facultades")+(Maestro!C11:C70='Resumen Ejecutivo'!E3)>0)*(('Resumen Ejecutivo'!H3="Todos los periodos")+(Maestro!BV11:BV70='Resumen Ejecutivo'!H3)>0)))*100,0),0)} -> 0 | K15: GER. PLANEACIÓN | M15: {=IFERROR(ROUND((SUMPRODUCT(((('Resumen Ejecutivo'!C3="Todas las modalidades")+(Maestro!F11:F70='Resumen Ejecutivo'!C3)>0)*(('Resumen Ejecutivo'!E3="Todas las facultades")+(Maestro!C11:C70='Resumen Ejecutivo'!E3)>0)*(('Resumen Ejecutivo'!H3="Todos los periodos")+(Maestro!BV11:BV70='Resumen Ejecutivo'!H3)>0))*(NOT(ISNUMBER(SEARCH("sin iniciar",Maestro!AI11:AI70)))*NOT(ISNUMBER(SEARCH("no aplica",Maestro!AI11:AI70)))*(Maestro!AI11:AI70<>"")*1))+(0)*0.5)/SUMPRODUCT(((('Resumen Ejecutivo'!C3="Todas las modalidades")+(Maestro!F11:F70='Resumen Ejecutivo'!C3)>0)*(('Resumen Ejecutivo'!E3="Todas las facultades")+(Maestro!C11:C70='Resumen Ejecutivo'!E3)>0)*(('Resumen Ejecutivo'!H3="Todos los periodos")+(Maestro!BV11:BV70='Resumen Ejecutivo'!H3)>0)))*100,0),0)} -> 0
B17: {=CONCATENATE("✔ ",TEXT(SUMPRODUCT(((('Resumen Ejecutivo'!C3="Todas las modalidades")+(Maestro!F11:F70='Resumen Ejecutivo'!C3)>0)*(('Resumen Ejecutivo'!E3="Todas las facultades")+(Maestro!C11:C70='Resumen Ejecutivo'!E3)>0)*(('Resumen Ejecutivo'!H3="Todos los periodos")+(Maestro!BV11:BV70='Resumen Ejecutivo'!H3)>0))*ISNUMBER(SEARCH("finalizado",Maestro!J11:J70))*1),"0")," Final. ◑ ",TEXT(SUMPRODUCT(((('Resumen Ejecutivo'!C3="Todas las modalidades")+(Maestro!F11:F70='Resumen Ejecutivo'!C3)>0)*(('Resumen Ejecutivo'!E3="Todas las facultades")+(Maestro!C11:C70='Resumen Ejecutivo'!E3)>0)*(('Resumen Ejecutivo'!H3="Todos los periodos")+(Maestro!BV11:BV70='Resumen Ejecutivo'!H3)>0))*ISNUMBER(SEARCH("en proceso",Maestro!J11:J70))*1),"0")," En proc. ○ ",TEXT(SUMPRODUCT(((('Resumen Ejecutivo'!C3="Todas las modalidades")+(Maestro!F11:F70='Resumen Ejecutivo'!C3)>0)*(('Resumen Ejecutivo'!E3="Todas las facultades")+(Maestro!C11:C70='Resumen Ejecutivo'!E3)>0)*(('Resumen Ejecutivo'!H3="Todos los periodos")+(Maestro!BV11:BV70='Resumen Ejecutivo'!H3)>0)))-SUMPRODUCT(((('Resumen Ejecutivo'!C3="Todas las modalidades")+(Maestro!F11:F70='Resumen Ejecutivo'!C3)>0)*(('Resumen Ejecutivo'!E3="Todas las facultades")+(Maestro!C11:C70='Resumen Ejecutivo'!E3)>0)*(('Resumen Ejecutivo'!H3="Todos los periodos")+(Maestro!BV11:BV70='Resumen Ejecutivo'!H3)>0))*ISNUMBER(SEARCH("finalizado",Maestro!J11:J70))*1)-SUMPRODUCT(((('Resumen Ejecutivo'!C3="Todas las modalidades")+(Maestro!F11:F70='Resumen Ejecutivo'!C3)>0)*(('Resumen Ejecutivo'!E3="Todas las facultades")+(Maestro!C11:C70='Resumen Ejecutivo'!E3)>0)*(('Resumen Ejecutivo'!H3="Todos los periodos")+(Maestro!BV11:BV70='Resumen Ejecutivo'!H3)>0))*ISNUMBER(SEARCH("en proceso",Maestro!J11:J70))*1)-SUMPRODUCT(((('Resumen Ejecutivo'!C3="Todas las modalidades")+(Maestro!F11:F70='Resumen Ejecutivo'!C3)>0)*(('Resumen Ejecutivo'!E3="Todas las facultades")+(Maestro!C11:C70='Resumen Ejecutivo'!E3)>0)*(('Resumen Ejecutivo'!H3="Todos los periodos")+(Maestro!BV11:BV70='Resumen Ejecutivo'!H3)>0))*ISNUMBER(SEARCH("no aplica",Maestro!J11:J70))*1),"0")," Sin inic. — ",TEXT(SUMPRODUCT(((('Resumen Ejecutivo'!C3="Todas las modalidades")+(Maestro!F11:F70='Resumen Ejecutivo'!C3)>0)*(('Resumen Ejecutivo'!E3="Todas las facultades")+(Maestro!C11:C70='Resumen Ejecutivo'!E3)>0)*(('Resumen Ejecutivo'!H3="Todos los periodos")+(Maestro!BV11:BV70='Resumen Ejecutivo'!H3)>0))*ISNUMBER(SEARCH("no aplica",Maestro!J11:J70))*1),"0")," N/A")} -> ✔ 0 Final. ◑ 0 En proc. ○ 0 Sin inic. — 0 N/A | E17: {=CONCATENATE("✔ ",TEXT(SUMPRODUCT(((('Resumen Ejecutivo'!C3="Todas las modalidades")+(Maestro!F11:F70='Resumen Ejecutivo'!C3)>0)*(('Resumen Ejecutivo'!E3="Todas las facultades")+(Maestro!C11:C70='Resumen Ejecutivo'!E3)>0)*(('Resumen Ejecutivo'!H3="Todos los periodos")+(Maestro!BV11:BV70='Resumen Ejecutivo'!H3)>0))*ISNUMBER(SEARCH("finalizado",Maestro!Y11:Y70))*1),"0")," Final. ◑ ",TEXT(SUMPRODUCT(((('Resumen Ejecutivo'!C3="Todas las modalidades")+(Maestro!F11:F70='Resumen Ejecutivo'!C3)>0)*(('Resumen Ejecutivo'!E3="Todas las facultades")+(Maestro!C11:C70='Resumen Ejecutivo'!E3)>0)*(('Resumen Ejecutivo'!H3="Todos los periodos")+(Maestro!BV11:BV70='Resumen Ejecutivo'!H3)>0))*ISNUMBER(SEARCH("en proceso",Maestro!Y11:Y70))*1),"0")," En proc. ○ ",TEXT(SUMPRODUCT(((('Resumen Ejecutivo'!C3="Todas las modalidades")+(Maestro!F11:F70='Resumen Ejecutivo'!C3)>0)*(('Resumen Ejecutivo'!E3="Todas las facultades")+(Maestro!C11:C70='Resumen Ejecutivo'!E3)>0)*(('Resumen Ejecutivo'!H3="Todos los periodos")+(Maestro!BV11:BV70='Resumen Ejecutivo'!H3)>0)))-SUMPRODUCT(((('Resumen Ejecutivo'!C3="Todas las modalidades")+(Maestro!F11:F70='Resumen Ejecutivo'!C3)>0)*(('Resumen Ejecutivo'!E3="Todas las facultades")+(Maestro!C11:C70='Resumen Ejecutivo'!E3)>0)*(('Resumen Ejecutivo'!H3="Todos los periodos")+(Maestro!BV11:BV70='Resumen Ejecutivo'!H3)>0))*ISNUMBER(SEARCH("finalizado",Maestro!Y11:Y70))*1)-SUMPRODUCT(((('Resumen Ejecutivo'!C3="Todas las modalidades")+(Maestro!F11:F70='Resumen Ejecutivo'!C3)>0)*(('Resumen Ejecutivo'!E3="Todas las facultades")+(Maestro!C11:C70='Resumen Ejecutivo'!E3)>0)*(('Resumen Ejecutivo'!H3="Todos los periodos")+(Maestro!BV11:BV70='Resumen Ejecutivo'!H3)>0))*ISNUMBER(SEARCH("en proceso",Maestro!Y11:Y70))*1)-SUMPRODUCT(((('Resumen Ejecutivo'!C3="Todas las modalidades")+(Maestro!F11:F70='Resumen Ejecutivo'!C3)>0)*(('Resumen Ejecutivo'!E3="Todas las facultades")+(Maestro!C11:C70='Resumen Ejecutivo'!E3)>0)*(('Resumen Ejecutivo'!H3="Todos los periodos")+(Maestro!BV11:BV70='Resumen Ejecutivo'!H3)>0))*ISNUMBER(SEARCH("no aplica",Maestro!Y11:Y70))*1),"0")," Sin inic. — ",TEXT(SUMPRODUCT(((('Resumen Ejecutivo'!C3="Todas las modalidades")+(Maestro!F11:F70='Resumen Ejecutivo'!C3)>0)*(('Resumen Ejecutivo'!E3="Todas las facultades")+(Maestro!C11:C70='Resumen Ejecutivo'!E3)>0)*(('Resumen Ejecutivo'!H3="Todos los periodos")+(Maestro!BV11:BV70='Resumen Ejecutivo'!H3)>0))*ISNUMBER(SEARCH("no aplica",Maestro!Y11:Y70))*1),"0")," N/A")} -> ✔ 0 Final. ◑ 0 En proc. ○ 0 Sin inic. — 0 N/A | H17: {=CONCATENATE("✔ ",TEXT(SUMPRODUCT(((('Resumen Ejecutivo'!C3="Todas las modalidades")+(Maestro!F11:F70='Resumen Ejecutivo'!C3)>0)*(('Resumen Ejecutivo'!E3="Todas las facultades")+(Maestro!C11:C70='Resumen Ejecutivo'!E3)>0)*(('Resumen Ejecutivo'!H3="Todos los periodos")+(Maestro!BV11:BV70='Resumen Ejecutivo'!H3)>0))*(ISNUMBER(SEARCH("resolución",Maestro!AB11:AB70))+ISNUMBER(SEARCH("aprobado",Maestro!AB11:AB70))+ISNUMBER(SEARCH("notificado",Maestro!AB11:AB70))>0)*1),"0")," Final. ◑ ",TEXT(SUMPRODUCT(((('Resumen Ejecutivo'!C3="Todas las modalidades")+(Maestro!F11:F70='Resumen Ejecutivo'!C3)>0)*(('Resumen Ejecutivo'!E3="Todas las facultades")+(Maestro!C11:C70='Resumen Ejecutivo'!E3)>0)*(('Resumen Ejecutivo'!H3="Todos los periodos")+(Maestro!BV11:BV70='Resumen Ejecutivo'!H3)>0))*(ISNUMBER(SEARCH("evaluación",Maestro!AB11:AB70))+ISNUMBER(SEARCH("elaboración",Maestro!AB11:AB70))+ISNUMBER(SEARCH("pares",Maestro!AB11:AB70))+ISNUMBER(SEARCH("completitud",Maestro!AB11:AB70))>0)*1),"0")," En proc. ○ ",TEXT(SUMPRODUCT(((('Resumen Ejecutivo'!C3="Todas las modalidades")+(Maestro!F11:F70='Resumen Ejecutivo'!C3)>0)*(('Resumen Ejecutivo'!E3="Todas las facultades")+(Maestro!C11:C70='Resumen Ejecutivo'!E3)>0)*(('Resumen Ejecutivo'!H3="Todos los periodos")+(Maestro!BV11:BV70='Resumen Ejecutivo'!H3)>0)))-SUMPRODUCT(((('Resumen Ejecutivo'!C3="Todas las modalidades")+(Maestro!F11:F70='Resumen Ejecutivo'!C3)>0)*(('Resumen Ejecutivo'!E3="Todas las facultades")+(Maestro!C11:C70='Resumen Ejecutivo'!E3)>0)*(('Resumen Ejecutivo'!H3="Todos los periodos")+(Maestro!BV11:BV70='Resumen Ejecutivo'!H3)>0))*(ISNUMBER(SEARCH("resolución",Maestro!AB11:AB70))+ISNUMBER(SEARCH("aprobado",Maestro!AB11:AB70))+ISNUMBER(SEARCH("notificado",Maestro!AB11:AB70))>0)*1)-SUMPRODUCT(((('Resumen Ejecutivo'!C3="Todas las modalidades")+(Maestro!F11:F70='Resumen Ejecutivo'!C3)>0)*(('Resumen Ejecutivo'!E3="Todas las facultades")+(Maestro!C11:C70='Resumen Ejecutivo'!E3)>0)*(('Resumen Ejecutivo'!H3="Todos los periodos")+(Maestro!BV11:BV70='Resumen Ejecutivo'!H3)>0))*(ISNUMBER(SEARCH("evaluación",Maestro!AB11:AB70))+ISNUMBER(SEARCH("elaboración",Maestro!AB11:AB70))+ISNUMBER(SEARCH("pares",Maestro!AB11:AB70))+ISNUMBER(SEARCH("completitud",Maestro!AB11:AB70))>0)*1)-SUMPRODUCT(((('Resumen Ejecutivo'!C3="Todas las modalidades")+(Maestro!F11:F70='Resumen Ejecutivo'!C3)>0)*(('Resumen Ejecutivo'!E3="Todas las facultades")+(Maestro!C11:C70='Resumen Ejecutivo'!E3)>0)*(('Resumen Ejecutivo'!H3="Todos los periodos")+(Maestro!BV11:BV70='Resumen Ejecutivo'!H3)>0))*ISNUMBER(SEARCH("no aplica",Maestro!AB11:AB70))*1),"0")," Sin inic. — ",TEXT(SUMPRODUCT(((('Resumen Ejecutivo'!C3="Todas las modalidades")+(Maestro!F11:F70='Resumen Ejecutivo'!C3)>0)*(('Resumen Ejecutivo'!E3="Todas las facultades")+(Maestro!C11:C70='Resumen Ejecutivo'!E3)>0)*(('Resumen Ejecutivo'!H3="Todos los periodos")+(Maestro!BV11:BV70='Resumen Ejecutivo'!H3)>0))*ISNUMBER(SEARCH("no aplica",Maestro!AB11:AB70))*1),"0")," N/A")} -> ✔ 0 Final. ◑ 0 En proc. ○ 0 Sin inic. — 0 N/A | K17: {=CONCATENATE("✔ ",TEXT(SUMPRODUCT(((('Resumen Ejecutivo'!C3="Todas las modalidades")+(Maestro!F11:F70='Resumen Ejecutivo'!C3)>0)*(('Resumen Ejecutivo'!E3="Todas las facultades")+(Maestro!C11:C70='Resumen Ejecutivo'!E3)>0)*(('Resumen Ejecutivo'!H3="Todos los periodos")+(Maestro!BV11:BV70='Resumen Ejecutivo'!H3)>0))*(NOT(ISNUMBER(SEARCH("sin iniciar",Maestro!AI11:AI70)))*NOT(ISNUMBER(SEARCH("no aplica",Maestro!AI11:AI70)))*(Maestro!AI11:AI70<>"")*1)),"0")," Final. ◑ ",TEXT(0,"0")," En proc. ○ ",TEXT(SUMPRODUCT(((('Resumen Ejecutivo'!C3="Todas las modalidades")+(Maestro!F11:F70='Resumen Ejecutivo'!C3)>0)*(('Resumen Ejecutivo'!E3="Todas las facultades")+(Maestro!C11:C70='Resumen Ejecutivo'!E3)>0)*(('Resumen Ejecutivo'!H3="Todos los periodos")+(Maestro!BV11:BV70='Resumen Ejecutivo'!H3)>0)))-SUMPRODUCT(((('Resumen Ejecutivo'!C3="Todas las modalidades")+(Maestro!F11:F70='Resumen Ejecutivo'!C3)>0)*(('Resumen Ejecutivo'!E3="Todas las facultades")+(Maestro!C11:C70='Resumen Ejecutivo'!E3)>0)*(('Resumen Ejecutivo'!H3="Todos los periodos")+(Maestro!BV11:BV70='Resumen Ejecutivo'!H3)>0))*(NOT(ISNUMBER(SEARCH("sin iniciar",Maestro!AI11:AI70)))*NOT(ISNUMBER(SEARCH("no aplica",Maestro!AI11:AI70)))*(Maestro!AI11:AI70<>"")*1))-0-SUMPRODUCT(((('Resumen Ejecutivo'!C3="Todas las modalidades")+(Maestro!F11:F70='Resumen Ejecutivo'!C3)>0)*(('Resumen Ejecutivo'!E3="Todas las facultades")+(Maestro!C11:C70='Resumen Ejecutivo'!E3)>0)*(('Resumen Ejecutivo'!H3="Todos los periodos")+(Maestro!BV11:BV70='Resumen Ejecutivo'!H3)>0))*ISNUMBER(SEARCH("no aplica",Maestro!AI11:AI70))*1),"0")," Sin inic. — ",TEXT(SUMPRODUCT(((('Resumen Ejecutivo'!C3="Todas las modalidades")+(Maestro!F11:F70='Resumen Ejecutivo'!C3)>0)*(('Resumen Ejecutivo'!E3="Todas las facultades")+(Maestro!C11:C70='Resumen Ejecutivo'!E3)>0)*(('Resumen Ejecutivo'!H3="Todos los periodos")+(Maestro!BV11:BV70='Resumen Ejecutivo'!H3)>0))*ISNUMBER(SEARCH("no aplica",Maestro!AI11:AI70))*1),"0")," N/A")} -> ✔ 0 Final. ◑ 0 En proc. ○ 0 Sin inic. — 0 N/A
B19: PRODUCCIÓN CONTENIDOS | D19: {=IFERROR(ROUND((SUMPRODUCT(((('Resumen Ejecutivo'!C3="Todas las modalidades")+(Maestro!F11:F70='Resumen Ejecutivo'!C3)>0)*(('Resumen Ejecutivo'!E3="Todas las facultades")+(Maestro!C11:C70='Resumen Ejecutivo'!E3)>0)*(('Resumen Ejecutivo'!H3="Todos los periodos")+(Maestro!BV11:BV70='Resumen Ejecutivo'!H3)>0))*(ISNUMBER(Maestro!AQ11:AQ70)*(Maestro!AQ11:AQ70>=1))*1)+(SUMPRODUCT(((('Resumen Ejecutivo'!C3="Todas las modalidades")+(Maestro!F11:F70='Resumen Ejecutivo'!C3)>0)*(('Resumen Ejecutivo'!E3="Todas las facultades")+(Maestro!C11:C70='Resumen Ejecutivo'!E3)>0)*(('Resumen Ejecutivo'!H3="Todos los periodos")+(Maestro!BV11:BV70='Resumen Ejecutivo'!H3)>0))*(ISNUMBER(Maestro!AQ11:AQ70)*(Maestro!AQ11:AQ70>0)*(Maestro!AQ11:AQ70<1))*1))*0.5)/SUMPRODUCT(((('Resumen Ejecutivo'!C3="Todas las modalidades")+(Maestro!F11:F70='Resumen Ejecutivo'!C3)>0)*(('Resumen Ejecutivo'!E3="Todas las facultades")+(Maestro!C11:C70='Resumen Ejecutivo'!E3)>0)*(('Resumen Ejecutivo'!H3="Todos los periodos")+(Maestro!BV11:BV70='Resumen Ejecutivo'!H3)>0)))*100,0),0)} -> 0 | E19: CONVENIOS INSTITUCIONALES | G19: {=IFERROR(ROUND((SUMPRODUCT(((('Resumen Ejecutivo'!C3="Todas las modalidades")+(Maestro!F11:F70='Resumen Ejecutivo'!C3)>0)*(('Resumen Ejecutivo'!E3="Todas las facultades")+(Maestro!C11:C70='Resumen Ejecutivo'!E3)>0)*(('Resumen Ejecutivo'!H3="Todos los periodos")+(Maestro!BV11:BV70='Resumen Ejecutivo'!H3)>0))*(ISNUMBER(Maestro!AZ11:AZ70)*(Maestro!AZ11:AZ70>=1))*1)+(SUMPRODUCT(((('Resumen Ejecutivo'!C3="Todas las modalidades")+(Maestro!F11:F70='Resumen Ejecutivo'!C3)>0)*(('Resumen Ejecutivo'!E3="Todas las facultades")+(Maestro!C11:C70='Resumen Ejecutivo'!E3)>0)*(('Resumen Ejecutivo'!H3="Todos los periodos")+(Maestro!BV11:BV70='Resumen Ejecutivo'!H3)>0))*(ISNUMBER(Maestro!AZ11:AZ70)*(Maestro!AZ11:AZ70>0)*(Maestro!AZ11:AZ70<1))*1))*0.5)/SUMPRODUCT(((('Resumen Ejecutivo'!C3="Todas las modalidades")+(Maestro!F11:F70='Resumen Ejecutivo'!C3)>0)*(('Resumen Ejecutivo'!E3="Todas las facultades")+(Maestro!C11:C70='Resumen Ejecutivo'!E3)>0)*(('Resumen Ejecutivo'!H3="Todos los periodos")+(Maestro!BV11:BV70='Resumen Ejecutivo'!H3)>0)))*100,0),0)} -> 0 | H19: PARAMETRIZAR BANNER | J19: {=IFERROR(ROUND((SUMPRODUCT(((('Resumen Ejecutivo'!C3="Todas las modalidades")+(Maestro!F11:F70='Resumen Ejecutivo'!C3)>0)*(('Resumen Ejecutivo'!E3="Todas las facultades")+(Maestro!C11:C70='Resumen Ejecutivo'!E3)>0)*(('Resumen Ejecutivo'!H3="Todos los periodos")+(Maestro!BV11:BV70='Resumen Ejecutivo'!H3)>0))*(ISNUMBER(Maestro!BG11:BG70)*(Maestro!BG11:BG70>=1))*1)+(SUMPRODUCT(((('Resumen Ejecutivo'!C3="Todas las modalidades")+(Maestro!F11:F70='Resumen Ejecutivo'!C3)>0)*(('Resumen Ejecutivo'!E3="Todas las facultades")+(Maestro!C11:C70='Resumen Ejecutivo'!E3)>0)*(('Resumen Ejecutivo'!H3="Todos los periodos")+(Maestro!BV11:BV70='Resumen Ejecutivo'!H3)>0))*(ISNUMBER(Maestro!BG11:BG70)*(Maestro!BG11:BG70>0)*(Maestro!BG11:BG70<1))*1))*0.5)/SUMPRODUCT(((('Resumen Ejecutivo'!C3="Todas las modalidades")+(Maestro!F11:F70='Resumen Ejecutivo'!C3)>0)*(('Resumen Ejecutivo'!E3="Todas las facultades")+(Maestro!C11:C70='Resumen Ejecutivo'!E3)>0)*(('Resumen Ejecutivo'!H3="Todos los periodos")+(Maestro!BV11:BV70='Resumen Ejecutivo'!H3)>0)))*100,0),0)} -> 0 | K19: PUBLICACIÓN WEB | M19: {=IFERROR(ROUND((SUMPRODUCT(((('Resumen Ejecutivo'!C3="Todas las modalidades")+(Maestro!F11:F70='Resumen Ejecutivo'!C3)>0)*(('Resumen Ejecutivo'!E3="Todas las facultades")+(Maestro!C11:C70='Resumen Ejecutivo'!E3)>0)*(('Resumen Ejecutivo'!H3="Todos los periodos")+(Maestro!BV11:BV70='Resumen Ejecutivo'!H3)>0))*(ISNUMBER(Maestro!BL11:BL70)*(Maestro!BL11:BL70>=1))*1)+(SUMPRODUCT(((('Resumen Ejecutivo'!C3="Todas las modalidades")+(Maestro!F11:F70='Resumen Ejecutivo'!C3)>0)*(('Resumen Ejecutivo'!E3="Todas las facultades")+(Maestro!C11:C70='Resumen Ejecutivo'!E3)>0)*(('Resumen Ejecutivo'!H3="Todos los periodos")+(Maestro!BV11:BV70='Resumen Ejecutivo'!H3)>0))*(ISNUMBER(Maestro!BL11:BL70)*(Maestro!BL11:BL70>0)*(Maestro!BL11:BL70<1))*1))*0.5)/SUMPRODUCT(((('Resumen Ejecutivo'!C3="Todas las modalidades")+(Maestro!F11:F70='Resumen Ejecutivo'!C3)>0)*(('Resumen Ejecutivo'!E3="Todas las facultades")+(Maestro!C11:C70='Resumen Ejecutivo'!E3)>0)*(('Resumen Ejecutivo'!H3="Todos los periodos")+(Maestro!BV11:BV70='Resumen Ejecutivo'!H3)>0)))*100,0),0)} -> 0
B21: {=CONCATENATE("✔ ",TEXT(SUMPRODUCT(((('Resumen Ejecutivo'!C3="Todas las modalidades")+(Maestro!F11:F70='Resumen Ejecutivo'!C3)>0)*(('Resumen Ejecutivo'!E3="Todas las facultades")+(Maestro!C11:C70='Resumen Ejecutivo'!E3)>0)*(('Resumen Ejecutivo'!H3="Todos los periodos")+(Maestro!BV11:BV70='Resumen Ejecutivo'!H3)>0))*(ISNUMBER(Maestro!AQ11:AQ70)*(Maestro!AQ11:AQ70>=1))*1),"0")," Final. ◑ ",TEXT(SUMPRODUCT(((('Resumen Ejecutivo'!C3="Todas las modalidades")+(Maestro!F11:F70='Resumen Ejecutivo'!C3)>0)*(('Resumen Ejecutivo'!E3="Todas las facultades")+(Maestro!C11:C70='Resumen Ejecutivo'!E3)>0)*(('Resumen Ejecutivo'!H3="Todos los periodos")+(Maestro!BV11:BV70='Resumen Ejecutivo'!H3)>0))*(ISNUMBER(Maestro!AQ11:AQ70)*(Maestro!AQ11:AQ70>0)*(Maestro!AQ11:AQ70<1))*1),"0")," En proc. ○ ",TEXT(SUMPRODUCT(((('Resumen Ejecutivo'!C3="Todas las modalidades")+(Maestro!F11:F70='Resumen Ejecutivo'!C3)>0)*(('Resumen Ejecutivo'!E3="Todas las facultades")+(Maestro!C11:C70='Resumen Ejecutivo'!E3)>0)*(('Resumen Ejecutivo'!H3="Todos los periodos")+(Maestro!BV11:BV70='Resumen Ejecutivo'!H3)>0)))-SUMPRODUCT(((('Resumen Ejecutivo'!C3="Todas las modalidades")+(Maestro!F11:F70='Resumen Ejecutivo'!C3)>0)*(('Resumen Ejecutivo'!E3="Todas las facultades")+(Maestro!C11:C70='Resumen Ejecutivo'!E3)>0)*(('Resumen Ejecutivo'!H3="Todos los periodos")+(Maestro!BV11:BV70='Resumen Ejecutivo'!H3)>0))*(ISNUMBER(Maestro!AQ11:AQ70)*(Maestro!AQ11:AQ70>=1))*1)-SUMPRODUCT(((('Resumen Ejecutivo'!C3="Todas las modalidades")+(Maestro!F11:F70='Resumen Ejecutivo'!C3)>0)*(('Resumen Ejecutivo'!E3="Todas las facultades")+(Maestro!C11:C70='Resumen Ejecutivo'!E3)>0)*(('Resumen Ejecutivo'!H3="Todos los periodos")+(Maestro!BV11:BV70='Resumen Ejecutivo'!H3)>0))*(ISNUMBER(Maestro!AQ11:AQ70)*(Maestro!AQ11:AQ70>0)*(Maestro!AQ11:AQ70<1))*1)-SUMPRODUCT(((('Resumen Ejecutivo'!C3="Todas las modalidades")+(Maestro!F11:F70='Resumen Ejecutivo'!C3)>0)*(('Resumen Ejecutivo'!E3="Todas las facultades")+(Maestro!C11:C70='Resumen Ejecutivo'!E3)>0)*(('Resumen Ejecutivo'!H3="Todos los periodos")+(Maestro!BV11:BV70='Resumen Ejecutivo'!H3)>0))*ISNUMBER(SEARCH("no aplica",Maestro!AQ11:AQ70))*1),"0")," Sin inic. — ",TEXT(SUMPRODUCT(((('Resumen Ejecutivo'!C3="Todas las modalidades")+(Maestro!F11:F70='Resumen Ejecutivo'!C3)>0)*(('Resumen Ejecutivo'!E3="Todas las facultades")+(Maestro!C11:C70='Resumen Ejecutivo'!E3)>0)*(('Resumen Ejecutivo'!H3="Todos los periodos")+(Maestro!BV11:BV70='Resumen Ejecutivo'!H3)>0))*ISNUMBER(SEARCH("no aplica",Maestro!AQ11:AQ70))*1),"0")," N/A")} -> ✔ 0 Final. ◑ 0 En proc. ○ 0 Sin inic. — 0 N/A | E21: {=CONCATENATE("✔ ",TEXT(SUMPRODUCT(((('Resumen Ejecutivo'!C3="Todas las modalidades")+(Maestro!F11:F70='Resumen Ejecutivo'!C3)>0)*(('Resumen Ejecutivo'!E3="Todas las facultades")+(Maestro!C11:C70='Resumen Ejecutivo'!E3)>0)*(('Resumen Ejecutivo'!H3="Todos los periodos")+(Maestro!BV11:BV70='Resumen Ejecutivo'!H3)>0))*(ISNUMBER(Maestro!AZ11:AZ70)*(Maestro!AZ11:AZ70>=1))*1),"0")," Final. ◑ ",TEXT(SUMPRODUCT(((('Resumen Ejecutivo'!C3="Todas las modalidades")+(Maestro!F11:F70='Resumen Ejecutivo'!C3)>0)*(('Resumen Ejecutivo'!E3="Todas las facultades")+(Maestro!C11:C70='Resumen Ejecutivo'!E3)>0)*(('Resumen Ejecutivo'!H3="Todos los periodos")+(Maestro!BV11:BV70='Resumen Ejecutivo'!H3)>0))*(ISNUMBER(Maestro!AZ11:AZ70)*(Maestro!AZ11:AZ70>0)*(Maestro!AZ11:AZ70<1))*1),"0")," En proc. ○ ",TEXT(SUMPRODUCT(((('Resumen Ejecutivo'!C3="Todas las modalidades")+(Maestro!F11:F70='Resumen Ejecutivo'!C3)>0)*(('Resumen Ejecutivo'!E3="Todas las facultades")+(Maestro!C11:C70='Resumen Ejecutivo'!E3)>0)*(('Resumen Ejecutivo'!H3="Todos los periodos")+(Maestro!BV11:BV70='Resumen Ejecutivo'!H3)>0)))-SUMPRODUCT(((('Resumen Ejecutivo'!C3="Todas las modalidades")+(Maestro!F11:F70='Resumen Ejecutivo'!C3)>0)*(('Resumen Ejecutivo'!E3="Todas las facultades")+(Maestro!C11:C70='Resumen Ejecutivo'!E3)>0)*(('Resumen Ejecutivo'!H3="Todos los periodos")+(Maestro!BV11:BV70='Resumen Ejecutivo'!H3)>0))*(ISNUMBER(Maestro!AZ11:AZ70)*(Maestro!AZ11:AZ70>=1))*1)-SUMPRODUCT(((('Resumen Ejecutivo'!C3="Todas las modalidades")+(Maestro!F11:F70='Resumen Ejecutivo'!C3)>0)*(('Resumen Ejecutivo'!E3="Todas las facultades")+(Maestro!C11:C70='Resumen Ejecutivo'!E3)>0)*(('Resumen Ejecutivo'!H3="Todos los periodos")+(Maestro!BV11:BV70='Resumen Ejecutivo'!H3)>0))*(ISNUMBER(Maestro!AZ11:AZ70)*(Maestro!AZ11:AZ70>0)*(Maestro!AZ11:AZ70<1))*1)-SUMPRODUCT(((('Resumen Ejecutivo'!C3="Todas las modalidades")+(Maestro!F11:F70='Resumen Ejecutivo'!C3)>0)*(('Resumen Ejecutivo'!E3="Todas las facultades")+(Maestro!C11:C70='Resumen Ejecutivo'!E3)>0)*(('Resumen Ejecutivo'!H3="Todos los periodos")+(Maestro!BV11:BV70='Resumen Ejecutivo'!H3)>0))*ISNUMBER(SEARCH("no aplica",Maestro!AZ11:AZ70))*1),"0")," Sin inic. — ",TEXT(SUMPRODUCT(((('Resumen Ejecutivo'!C3="Todas las modalidades")+(Maestro!F11:F70='Resumen Ejecutivo'!C3)>0)*(('Resumen Ejecutivo'!E3="Todas las facultades")+(Maestro!C11:C70='Resumen Ejecutivo'!E3)>0)*(('Resumen Ejecutivo'!H3="Todos los periodos")+(Maestro!BV11:BV70='Resumen Ejecutivo'!H3)>0))*ISNUMBER(SEARCH("no aplica",Maestro!AZ11:AZ70))*1),"0")," N/A")} -> ✔ 0 Final. ◑ 0 En proc. ○ 0 Sin inic. — 0 N/A | H21: {=CONCATENATE("✔ ",TEXT(SUMPRODUCT(((('Resumen Ejecutivo'!C3="Todas las modalidades")+(Maestro!F11:F70='Resumen Ejecutivo'!C3)>0)*(('Resumen Ejecutivo'!E3="Todas las facultades")+(Maestro!C11:C70='Resumen Ejecutivo'!E3)>0)*(('Resumen Ejecutivo'!H3="Todos los periodos")+(Maestro!BV11:BV70='Resumen Ejecutivo'!H3)>0))*(ISNUMBER(Maestro!BG11:BG70)*(Maestro!BG11:BG70>=1))*1),"0")," Final. ◑ ",TEXT(SUMPRODUCT(((('Resumen Ejecutivo'!C3="Todas las modalidades")+(Maestro!F11:F70='Resumen Ejecutivo'!C3)>0)*(('Resumen Ejecutivo'!E3="Todas las facultades")+(Maestro!C11:C70='Resumen Ejecutivo'!E3)>0)*(('Resumen Ejecutivo'!H3="Todos los periodos")+(Maestro!BV11:BV70='Resumen Ejecutivo'!H3)>0))*(ISNUMBER(Maestro!BG11:BG70)*(Maestro!BG11:BG70>0)*(Maestro!BG11:BG70<1))*1),"0")," En proc. ○ ",TEXT(SUMPRODUCT(((('Resumen Ejecutivo'!C3="Todas las modalidades")+(Maestro!F11:F70='Resumen Ejecutivo'!C3)>0)*(('Resumen Ejecutivo'!E3="Todas las facultades")+(Maestro!C11:C70='Resumen Ejecutivo'!E3)>0)*(('Resumen Ejecutivo'!H3="Todos los periodos")+(Maestro!BV11:BV70='Resumen Ejecutivo'!H3)>0)))-SUMPRODUCT(((('Resumen Ejecutivo'!C3="Todas las modalidades")+(Maestro!F11:F70='Resumen Ejecutivo'!C3)>0)*(('Resumen Ejecutivo'!E3="Todas las facultades")+(Maestro!C11:C70='Resumen Ejecutivo'!E3)>0)*(('Resumen Ejecutivo'!H3="Todos los periodos")+(Maestro!BV11:BV70='Resumen Ejecutivo'!H3)>0))*(ISNUMBER(Maestro!BG11:BG70)*(Maestro!BG11:BG70>=1))*1)-SUMPRODUCT(((('Resumen Ejecutivo'!C3="Todas las modalidades")+(Maestro!F11:F70='Resumen Ejecutivo'!C3)>0)*(('Resumen Ejecutivo'!E3="Todas las facultades")+(Maestro!C11:C70='Resumen Ejecutivo'!E3)>0)*(('Resumen Ejecutivo'!H3="Todos los periodos")+(Maestro!BV11:BV70='Resumen Ejecutivo'!H3)>0))*(ISNUMBER(Maestro!BG11:BG70)*(Maestro!BG11:BG70>0)*(Maestro!BG11:BG70<1))*1)-SUMPRODUCT(((('Resumen Ejecutivo'!C3="Todas las modalidades")+(Maestro!F11:F70='Resumen Ejecutivo'!C3)>0)*(('Resumen Ejecutivo'!E3="Todas las facultades")+(Maestro!C11:C70='Resumen Ejecutivo'!E3)>0)*(('Resumen Ejecutivo'!H3="Todos los periodos")+(Maestro!BV11:BV70='Resumen Ejecutivo'!H3)>0))*ISNUMBER(SEARCH("no aplica",Maestro!BG11:BG70))*1),"0")," Sin inic. — ",TEXT(SUMPRODUCT(((('Resumen Ejecutivo'!C3="Todas las modalidades")+(Maestro!F11:F70='Resumen Ejecutivo'!C3)>0)*(('Resumen Ejecutivo'!E3="Todas las facultades")+(Maestro!C11:C70='Resumen Ejecutivo'!E3)>0)*(('Resumen Ejecutivo'!H3="Todos los periodos")+(Maestro!BV11:BV70='Resumen Ejecutivo'!H3)>0))*ISNUMBER(SEARCH("no aplica",Maestro!BG11:BG70))*1),"0")," N/A")} -> ✔ 0 Final. ◑ 0 En proc. ○ 0 Sin inic. — 0 N/A | K21: {=CONCATENATE("✔ ",TEXT(SUMPRODUCT(((('Resumen Ejecutivo'!C3="Todas las modalidades")+(Maestro!F11:F70='Resumen Ejecutivo'!C3)>0)*(('Resumen Ejecutivo'!E3="Todas las facultades")+(Maestro!C11:C70='Resumen Ejecutivo'!E3)>0)*(('Resumen Ejecutivo'!H3="Todos los periodos")+(Maestro!BV11:BV70='Resumen Ejecutivo'!H3)>0))*(ISNUMBER(Maestro!BL11:BL70)*(Maestro!BL11:BL70>=1))*1),"0")," Final. ◑ ",TEXT(SUMPRODUCT(((('Resumen Ejecutivo'!C3="Todas las modalidades")+(Maestro!F11:F70='Resumen Ejecutivo'!C3)>0)*(('Resumen Ejecutivo'!E3="Todas las facultades")+(Maestro!C11:C70='Resumen Ejecutivo'!E3)>0)*(('Resumen Ejecutivo'!H3="Todos los periodos")+(Maestro!BV11:BV70='Resumen Ejecutivo'!H3)>0))*(ISNUMBER(Maestro!BL11:BL70)*(Maestro!BL11:BL70>0)*(Maestro!BL11:BL70<1))*1),"0")," En proc. ○ ",TEXT(SUMPRODUCT(((('Resumen Ejecutivo'!C3="Todas las modalidades")+(Maestro!F11:F70='Resumen Ejecutivo'!C3)>0)*(('Resumen Ejecutivo'!E3="Todas las facultades")+(Maestro!C11:C70='Resumen Ejecutivo'!E3)>0)*(('Resumen Ejecutivo'!H3="Todos los periodos")+(Maestro!BV11:BV70='Resumen Ejecutivo'!H3)>0)))-SUMPRODUCT(((('Resumen Ejecutivo'!C3="Todas las modalidades")+(Maestro!F11:F70='Resumen Ejecutivo'!C3)>0)*(('Resumen Ejecutivo'!E3="Todas las facultades")+(Maestro!C11:C70='Resumen Ejecutivo'!E3)>0)*(('Resumen Ejecutivo'!H3="Todos los periodos")+(Maestro!BV11:BV70='Resumen Ejecutivo'!H3)>0))*(ISNUMBER(Maestro!BL11:BL70)*(Maestro!BL11:BL70>=1))*1)-SUMPRODUCT(((('Resumen Ejecutivo'!C3="Todas las modalidades")+(Maestro!F11:F70='Resumen Ejecutivo'!C3)>0)*(('Resumen Ejecutivo'!E3="Todas las facultades")+(Maestro!C11:C70='Resumen Ejecutivo'!E3)>0)*(('Resumen Ejecutivo'!H3="Todos los periodos")+(Maestro!BV11:BV70='Resumen Ejecutivo'!H3)>0))*(ISNUMBER(Maestro!BL11:BL70)*(Maestro!BL11:BL70>0)*(Maestro!BL11:BL70<1))*1)-SUMPRODUCT(((('Resumen Ejecutivo'!C3="Todas las modalidades")+(Maestro!F11:F70='Resumen Ejecutivo'!C3)>0)*(('Resumen Ejecutivo'!E3="Todas las facultades")+(Maestro!C11:C70='Resumen Ejecutivo'!E3)>0)*(('Resumen Ejecutivo'!H3="Todos los periodos")+(Maestro!BV11:BV70='Resumen Ejecutivo'!H3)>0))*ISNUMBER(SEARCH("no aplica",Maestro!BL11:BL70))*1),"0")," Sin inic. — ",TEXT(SUMPRODUCT(((('Resumen Ejecutivo'!C3="Todas las modalidades")+(Maestro!F11:F70='Resumen Ejecutivo'!C3)>0)*(('Resumen Ejecutivo'!E3="Todas las facultades")+(Maestro!C11:C70='Resumen Ejecutivo'!E3)>0)*(('Resumen Ejecutivo'!H3="Todos los periodos")+(Maestro!BV11:BV70='Resumen Ejecutivo'!H3)>0))*ISNUMBER(SEARCH("no aplica",Maestro!BL11:BL70))*1),"0")," N/A")} -> ✔ 0 Final. ◑ 0 En proc. ○ 0 Sin inic. — 0 N/A
B24: ESTADO POR ETAPA | H24: AVANCE POR FACULTAD Y PROGRAMA
B26: PROCESO | C26: FINALIZ. | D26: EN PROC. | E26: SIN INIC. | F26: TOTAL | H26: FACULTAD / PROGRAMA | M26: AVANCE | N26: PROGRESO
B27: G. Académica | C27: 58 | D27: 2 | E27: 0 | F27: 60 | H27: ◆ Soc. Cultura y Creatividad | M27: 0.35 | N27: ███░░░░░
B28: G. Financiera | C28: 12 | D28: 14 | E28: 34 | F28: 60 | H28: Lic. Ciencias Sociales | M28: 0.8 | N28: ██████░░
B29: Aseg. Calidad | C29: 1 | D29: 56 | E29: 3 | F29: 60 | H29: Maest. Ger. Talento Humano | M29: 0.6 | N29: █████░░░
B30: Ger. Planeación | C30: 0 | D30: 0 | E30: 60 | F30: 60 | H30: Comunicación Social | M30: 0.46 | N30: ████░░░░
B31: Prod. Contenidos | C31: 4 | D31: 12 | E31: 44 | F31: 60 | H31: Tec. Mercadeo y Publicidad | M31: 0.45 | N31: ████░░░░
B32: Convenios | C32: 0 | D32: 2 | E32: 58 | F32: 60 | H32: Espec. Ger. Mercadeo | M32: 0.45 | N32: ████░░░░
B33: Param. Banner | C33: 5 | D33: 1 | E33: 54 | F33: 60 | H33: Técnica Prof. Judicial | M33: 0.43 | N33: ███░░░░░
B34: Pub. Web | C34: 0 | D34: 0 | E34: 60 | F34: 60 | H34: Maest. Ger. Estratégica | M34: 0.4 | N34: ███░░░░░
H35: Mercadeo y Publicidad | M35: 0.38 | N35: ███░░░░░
H37: ◆ Ing. Diseño e Innovación | M37: 0.28 | N37: ██░░░░░░
H38: Maest. Educación STEM | M38: 0.75 | N38: ██████░░
H39: Espec. Ger. Proy. BI | M39: 0.65 | N39: █████░░░
H40: Diseño Digital | M40: 0.35 | N40: ███░░░░░
H41: Lic. Educación Infantil | M41: 0.33 | N41: ███░░░░░
H42: Ing. Industrial Virtual | M42: 0.3 | N42: ██░░░░░░
H43: Diseño Gráfico | M43: 0.28 | N43: ██░░░░░░
H45: ◆ Negocios, Gestión y Sost. | M45: 0.3 | N45: ██░░░░░░
H46: Contaduría Pública Pres. | M46: 0.5 | N46: ████░░░░
H47: Contaduría Pública Virt. | M47: 0.45 | N47: ████░░░░
H48: Adm. Empresas Presencial | M48: 0.45 | N48: ████░░░░
... H50: Adm. Pública Virtual | M50: 0.25 | N50: ██░░░░░░
B52: DETALLE DE PROGRAMAS — 25 de 60 programas mostrados · ✔ = Finalizado ◑ = En proceso ○ = Sin iniciar
B53: PROGRAMA | C53: ESCUELA | D53: FACULTAD | E53: MODALIDAD | F53: NIVEL | G53: PERIODO | H53: G.ACAD | I53: G.FIN | J53: ASEG.C | K53: G.PLAN | L53: PROD.C | M53: CONV | N53: P.BAN | O53: P.WEB
...

Sheet Dashboard
B2: RESUMEN EJECUTIVO — REFORMA CURRICULAR: ESTADO DE ETAPAS
B4: Leyenda: | C4: ✔ Finalizado | E4: ⚡ En proceso | G4: ✖ Sin iniciar | I4: ⏳ Con avance (X/6) | K4: ✖ Sin avance (0/6)
B6: 1. ESTADO GLOBAL POR ETAPA (todos los programas)
B7: Etapa | C7: ✔ Fin. | D7: % Fin. | E7: ⚡ Proc. | F7: % Proc. | G7: ✖ Sin. | H7: % Sin. | I7: Sin dato | J7: TOTAL | K7: Barra de avance | L7: Estado
B8: PLAN DE VIRTUALIZACIÓN | C8: =COUNTIF(Maestro!R11:R70,"finalizado") -> 0 | D8: =IFERROR(C8/J8,0) -> 0 | E8: =COUNTIF(Maestro!R11:R70,"en proceso") -> 0 | F8: =IFERROR(E8/J8,0) -> 0 | G8: =COUNTIF(Maestro!R11:R70,"sin iniciar") -> 0 | H8: =IFERROR(G8/J8,0) -> 0 | I8: =J8-C8-E8-G8 -> 60 | J8: =COUNTA(Maestro!E11:E70) -> 60 | K8: =REPT("█",ROUND(D8*15,0))&REPT("░",15-ROUND(D8*15,0)) -> ░░░░░░░░░░░░░░░ | L8: =IF(D8=1,"✔ Completo",IF(C8+E8=0,"✖ Sin iniciar",IF(D8>=0.75,"⏫ Avanzado (≥75%)","⏳ En marcha"))) -> ✖ Sin iniciar
B9: CONCEPTO FINANCIERO | C9: =COUNTIF(Maestro!U11:U70,"finalizado") -> 1 | D9: =IFERROR(C9/J9,0) -> 0.016666667 | E9: =COUNTIF(Maestro!U11:U70,"en proceso") -> 0 | F9: =IFERROR(E9/J9,0) -> 0 | G9: =COUNTIF(Maestro!U11:U70,"sin iniciar") -> 0 | H9: =IFERROR(G9/J9,0) -> 0 | I9: =J9-C9-E9-G9 -> 59 | J9: =COUNTA(Maestro!E11:E70) -> 60 | K9: =REPT("█",ROUND(D9*15,0))&REPT("░",15-ROUND(D9*15,0)) -> ░░░░░░░░░░░░░░░ | L9: =IF(D9=1,"✔ Completo",IF(C9+E9=0,"✖ Sin iniciar",IF(D9>=0.75,"⏫ Avanzado (≥75%)","⏳ En marcha"))) -> ⏳ En marcha
B10: Acta de homologación | C10: =COUNTIF(Maestro!AR11:AR70,"finalizado") -> 0 | D10: =IFERROR(C10/J10,0) -> 0 | E10: =COUNTIF(Maestro!AR11:AR70,"en proceso") -> 0 | F10: =IFERROR(E10/J10,0) -> 0 | G10: =COUNTIF(Maestro!AR11:AR70,"sin iniciar") -> 0 | H10: =IFERROR(G10/J10,0) -> 0 | I10: =J10-C10-E10-G10 -> 60 | J10: =COUNTA(Maestro!E11:E70) -> 60 | K10: =REPT("█",ROUND(D10*15,0))&REPT("░",15-ROUND(D10*15,0)) -> ░░░░░░░░░░░░░░░ | L10: =IF(D10=1,"✔ Completo",IF(C10+E10=0,"✖ Sin iniciar",IF(D10>=0.75,"⏫ Avanzado (≥75%)","⏳ En marcha"))) -> ✖ Sin iniciar
B11: % avance contenidos virtuales | C11: =COUNTIF(Maestro!AQ11:AQ70,">=1") -> 0 | D11: =IFERROR(C11/J11,0) -> 0 | E11: =COUNTIFS(Maestro!AQ11:AQ70,">0",Maestro!AQ11:AQ70,"<1") -> 0 | F11: =IFERROR(E11/J11,0) -> 0 | G11: =COUNTIF(Maestro!AQ11:AQ70,0) -> 0 | H11: =IFERROR(G11/J11,0) -> 0 | I11: =J11-C11-E11-G11 -> 60 | J11: =COUNTA(Maestro!E11:E70) -> 60 | K11: =REPT("█",ROUND(D11*15,0))&REPT("░",15-ROUND(D11*15,0)) -> ░░░░░░░░░░░░░░░ | L11: =IF(D11=1,"✔ Completo",IF(C11+E11=0,"✖ Sin iniciar",IF(D11>=0.75,"⏫ Avanzado (≥75%)","⏳ En marcha"))) -> ✖ Sin iniciar
B12: Ruta sugerida homologación/articulación convenio | C12: =COUNTIF(Maestro!AS11:AS70,"finalizado") -> 0 | D12: =IFERROR(C12/J12,0) -> 0 | E12: =COUNTIF(Maestro!AS11:AS70,"en proceso") -> 0 | F12: =IFERROR(E12/J12,0) -> 0 | G12: =COUNTIF(Maestro!AS11:AS70,"sin iniciar") -> 0 | H12: =IFERROR(G12/J12,0) -> 0 | I12: =J12-C12-E12-G12 -> 60 | J12: =COUNTA(Maestro!E11:E70) -> 60 | K12: =REPT("█",ROUND(D12*15,0))&REPT("░",15-ROUND(D12*15,0)) -> ░░░░░░░░░░░░░░░ | L12: =IF(D12=1,"✔ Completo",IF(C12+E12=0,"✖ Sin iniciar",IF(D12>=0.75,"⏫ Avanzado (≥75%)","⏳ En marcha"))) -> ✖ Sin iniciar
B13: Aulas máster nueva | C13: =COUNTIF(Maestro!BD11:BD70,"finalizado") -> 0 | D13: =IFERROR(C13/J13,0) -> 0 | E13: =COUNTIF(Maestro!BD11:BD70,"en proceso") -> 0 | F13: =IFERROR(E13/J13,0) -> 0 | G13: =COUNTIF(Maestro!BD11:BD70,"sin iniciar") -> 0 | H13: =IFERROR(G13/J13,0) -> 0 | I13: =J13-C13-E13-G13 -> 60 | J13: =COUNTA(Maestro!E11:E70) -> 60 | K13: =REPT("█",ROUND(D13*15,0))&REPT("░",15-ROUND(D13*15,0)) -> ░░░░░░░░░░░░░░░ | L13: =IF(D13=1,"✔ Completo",IF(C13+E13=0,"✖ Sin iniciar",IF(D13>=0.75,"⏫ Avanzado (≥75%)","⏳ En marcha"))) -> ✖ Sin iniciar
B14: Aulas máster actualizada | C14: =COUNTIF(Maestro!BE11:BE70,"finalizado") -> 0 | D14: =IFERROR(C14/J14,0) -> 0 | E14: =COUNTIF(Maestro!BE11:BE70,"en proceso") -> 0 | F14: =IFERROR(E14/J14,0) -> 0 | G14: =COUNTIF(Maestro!BE11:BE70,"sin iniciar") -> 0 | H14: =IFERROR(G14/J14,0) -> 0 | I14: =J14-C14-E14-G14 -> 60 | J14: =COUNTA(Maestro!E11:E70) -> 60 | K14: =REPT("█",ROUND(D14*15,0))&REPT("░",15-ROUND(D14*15,0)) -> ░░░░░░░░░░░░░░░ | L14: =IF(D14=1,"✔ Completo",IF(C14+E14=0,"✖ Sin iniciar",IF(D14>=0.75,"⏫ Avanzado (≥75%)","⏳ En marcha"))) -> ✖ Sin iniciar
B15: Parametrizar y configurar actividades evaluativas | C15: =COUNTIF(Maestro!BF11:BF70,"finalizado") -> 0 | D15: =IFERROR(C15/J15,0) -> 0 | E15: =COUNTIF(Maestro!BF11:BF70,"en proceso") -> 0 | F15: =IFERROR(E15/J15,0) -> 0 | G15: =COUNTIF(Maestro!BF11:BF70,"sin iniciar") -> 0 | H15: =IFERROR(G15/J15,0) -> 0 | I15: =J15-C15-E15-G15 -> 60 | J15: =COUNTA(Maestro!E11:E70) -> 60 | K15: =REPT("█",ROUND(D15*15,0))&REPT("░",15-ROUND(D15*15,0)) -> ░░░░░░░░░░░░░░░ | L15: =IF(D15=1,"✔ Completo",IF(C15+E15=0,"✖ Sin iniciar",IF(D15>=0.75,"⏫ Avanzado (≥75%)","⏳ En marcha"))) -> ✖ Sin iniciar
B16: Configurar plan de estudios en Banner por MODALIDAD | C16: =COUNTIF(Maestro!BP11:BP70,"finalizado") -> 0 | D16: =IFERROR(C16/J16,0) -> 0 | E16: =COUNTIF(Maestro!BP11:BP70,"en proceso") -> 0 | F16: =IFERROR(E16/J16,0) -> 0 | G16: =COUNTIF(Maestro!BP11:BP70,"sin iniciar") -> 1 | H16: =IFERROR(G16/J16,0) -> 0.016666667 | I16: =J16-C16-E16-G16 -> 59 | J16: =COUNTA(Maestro!E11:E70) -> 60 | K16: =REPT("█",ROUND(D16*15,0))&REPT("░",15-ROUND(D16*15,0)) -> ░░░░░░░░░░░░░░░ | L16: =IF(D16=1,"✔ Completo",IF(C16+E16=0,"✖ Sin iniciar",IF(D16>=0.75,"⏫ Avanzado (≥75%)","⏳ En marcha"))) -> ✖ Sin iniciar
B18: 2. ESTADO POR MODALIDAD
C20: Etapa | D20: Presencial | G20: Virtual | J20: Híbrido
D21: ✔Fin | E21: ⚡Proc | F21: ✖Sin | G21: ✔Fin | H21: ⚡Proc | I21: ✖Sin | J21: ✔Fin | K21: ⚡Proc | L21: ✖Sin
B22: Agregar la fase académica | C22: Plan Virtualización | D22: =COUNTIFS(Maestro!F11:F70,"Presencial",Maestro!R11:R70,"finalizado") -> 0 | E22: =COUNTIFS(Maestro!F11:F70,"Presencial",Maestro!R11:R70,"en proceso") -> 0 | F22: =COUNTIFS(Maestro!F11:F70,"Presencial",Maestro!R11:R70,"sin iniciar") -> 0 | G22: =COUNTIFS(Maestro!F11:F70,"Virtual",Maestro!R11:R70,"finalizado") -> 0 | H22: =COUNTIFS(Maestro!F11:F70,"Virtual",Maestro!R11:R70,"en proceso") -> 0 | I22: =COUNTIFS(Maestro!F11:F70,"Virtual",Maestro!R11:R70,"sin iniciar") -> 0 | J22: =COUNTIFS(Maestro!F11:F70,"Híbrido",Maestro!R11:R70,"finalizado") -> 0 | K22: =COUNTIFS(Maestro!F11:F70,"Híbrido",Maestro!R11:R70,"en proceso") -> 0 | L22: =COUNTIFS(Maestro!F11:F70,"Híbrido",Maestro!R11:R70,"sin iniciar") -> 0
C23: Concepto Financiero | D23: =COUNTIFS(Maestro!F11:F70,"Presencial",Maestro!U11:U70,"finalizado") -> 0 | E23: =COUNTIFS(Maestro!F11:F70,"Presencial",Maestro!U11:U70,"en proceso") -> 0 | F23: =COUNTIFS(Maestro!F11:F70,"Presencial",Maestro!U11:U70,"sin iniciar") -> 0 | G23: =COUNTIFS(Maestro!F11:F70,"Virtual",Maestro!U11:U70,"finalizado") -> 1 | H23: =COUNTIFS(Maestro!F11:F70,"Virtual",Maestro!U11:U70,"en proceso") -> 0 | I23: =COUNTIFS(Maestro!F11:F70,"Virtual",Maestro!U11:U70,"sin iniciar") -> 0 | J23: =COUNTIFS(Maestro!F11:F70,"Híbrido",Maestro!U11:U70,"finalizado") -> 0 | K23: =COUNTIFS(Maestro!F11:F70,"Híbrido",Maestro!U11:U70,"en proceso") -> 0 | L23: =COUNTIFS(Maestro!F11:F70,"Híbrido",Maestro!U11:U70,"sin iniciar") -> 0
C24: Acta Homologación | D24: =COUNTIFS(Maestro!F11:F70,"Presencial",Maestro!AR11:AR70,"finalizado") -> 0 | E24: =COUNTIFS(Maestro!F11:F70,"Presencial",Maestro!AR11:AR70,"en proceso") -> 0 | F24: =COUNTIFS(Maestro!F11:F70,"Presencial",Maestro!AR11:AR70,"sin iniciar") -> 0 | G24: =COUNTIFS(Maestro!F11:F70,"Virtual",Maestro!AR11:AR70,"finalizado") -> 0 | H24: =COUNTIFS(Maestro!F11:F70,"Virtual",Maestro!AR11:AR70,"en proceso") -> 0 | I24: =COUNTIFS(Maestro!F11:F70,"Virtual",Maestro!AR11:AR70,"sin iniciar") -> 0 | J24: =COUNTIFS(Maestro!F11:F70,"Híbrido",Maestro!AR11:AR70,"finalizado") -> 0 | K24: =COUNTIFS(Maestro!F11:F70,"Híbrido",Maestro!AR11:AR70,"en proceso") -> 0 | L24: =COUNTIFS(Maestro!F11:F70,"Híbrido",Maestro!AR11:AR70,"sin iniciar") -> 0
C25: % Avance contenidos | D25: =COUNTIFS(Maestro!F11:F70,"Presencial",Maestro!AQ11:AQ70,">=1") -> 0 | E25: =COUNTIFS(Maestro!F11:F70,"Presencial",Maestro!AQ11:AQ70,">0",Maestro!AQ11:AQ70,"<1") -> 0 | F25: =COUNTIFS(Maestro!F11:F70,"Presencial",Maestro!AQ11:AQ70,0) -> 0 | G25: =COUNTIFS(Maestro!F11:F70,"Virtual",Maestro!AQ11:AQ70,">=1") -> 0 | H25: =COUNTIFS(Maestro!F11:F70,"Virtual",Maestro!AQ11:AQ70,">0",Maestro!AQ11:AQ70,"<1") -> 0 | I25: =COUNTIFS(Maestro!F11:F70,"Virtual",Maestro!AQ11:AQ70,0) -> 0 | J25: =COUNTIFS(Maestro!F11:F70,"Híbrido",Maestro!AQ11:AQ70,">=1") -> 0 | K25: =COUNTIFS(Maestro!F11:F70,"Híbrido",Maestro!AQ11:AQ70,">0",Maestro!AQ11:AQ70,"<1") -> 0 | L25: =COUNTIFS(Maestro!F11:F70,"Híbrido",Maestro!AQ11:AQ70,0) -> 0
C26: Ruta Homologación | D26: =COUNTIFS(Maestro!F11:F70,"Presencial",Maestro!AS11:AS70,"finalizado") -> 0 | E26: =COUNTIFS(Maestro!F11:F70,"Presencial",Maestro!AS11:AS70,"en proceso") -> 0 | F26: =COUNTIFS(Maestro!F11:F70,"Presencial",Maestro!AS11:AS70,"sin iniciar") -> 0 | G26: =COUNTIFS(Maestro!F11:F70,"Virtual",Maestro!AS11:AS70,"finalizado") -> 0 | H26: =COUNTIFS(Maestro!F11:F70,"Virtual",Maestro!AS11:AS70,"en proceso") -> 0 | I26: =COUNTIFS(Maestro!F11:F70,"Virtual",Maestro!AS11:AS70,"sin iniciar") -> 0 | J26: =COUNTIFS(Maestro!F11:F70,"Híbrido",Maestro!AS11:AS70,"finalizado") -> 0 | K26: =COUNTIFS(Maestro!F11:F70,"Híbrido",Maestro!AS11:AS70,"en proceso") -> 0 | L26: =COUNTIFS(Maestro!F11:F70,"Híbrido",Maestro!AS11:AS70,"sin iniciar") -> 0
C27: Aulas máster nueva | D27: =COUNTIFS(Maestro!F11:F70,"Presencial",Maestro!BD11:BD70,"finalizado") -> 0 | E27: =COUNTIFS(Maestro!F11:F70,"Presencial",Maestro!BD11:BD70,"en proceso") -> 0 | F27: =COUNTIFS(Maestro!F11:F70,"Presencial",Maestro!BD11:BD70,"sin iniciar") -> 0 | G27: =COUNTIFS(Maestro!F11:F70,"Virtual",Maestro!BD11:BD70,"finalizado") -> 0 | H27: =COUNTIFS(Maestro!F11:F70,"Virtual",Maestro!BD11:BD70,"en proceso") -> 0 | I27: =COUNTIFS(Maestro!F11:F70,"Virtual",Maestro!BD11:BD70,"sin iniciar") -> 0 | J27: =COUNTIFS(Maestro!F11:F70,"Híbrido",Maestro!BD11:BD70,"finalizado") -> 0 | K27: =COUNTIFS(Maestro!F11:F70,"Híbrido",Maestro!BD11:BD70,"en proceso") -> 0 | L27: =COUNTIFS(Maestro!F11:F70,"Híbrido",Maestro!BD11:BD70,"sin iniciar") -> 0
C28: Aulas máster actual. | D28: =COUNTIFS(Maestro!F11:F70,"Presencial",Maestro!BE11:BE70,"finalizado") -> 0 | E28: =COUNTIFS(Maestro!F11:F70,"Presencial",Maestro!BE11:BE70,"en proceso") -> 0 | F28: =COUNTIFS(Maestro!F11:F70,"Presencial",Maestro!BE11:BE70,"sin iniciar") -> 0 | G28: =COUNTIFS(Maestro!F11:F70,"Virtual",Maestro!BE11:BE70,"finalizado") -> 0 | H28: =COUNTIFS(Maestro!F11:F70,"Virtual",Maestro!BE11:BE70,"en proceso") -> 0 | I28: =COUNTIFS(Maestro!F11:F70,"Virtual",Maestro!BE11:BE70,"sin iniciar") -> 0 | J28: =COUNTIFS(Maestro!F11:F70,"Híbrido",Maestro!BE11:BE70,"finalizado") -> 0 | K28: =COUNTIFS(Maestro!F11:F70,"Híbrido",Maestro!BE11:BE70,"en proceso") -> 0 | L28: =COUNTIFS(Maestro!F11:F70,"Híbrido",Maestro!BE11:BE70,"sin iniciar") -> 0
C29: Conf. activid. eval. | D29: =COUNTIFS(Maestro!F11:F70,"Presencial",Maestro!BF11:BF70,"finalizado") -> 0 | E29: =COUNTIFS(Maestro!F11:F70,"Presencial",Maestro!BF11:BF70,"en proceso") -> 0 | F29: =COUNTIFS(Maestro!F11:F70,"Presencial",Maestro!BF11:BF70,"sin iniciar") -> 0 | G29: =COUNTIFS(Maestro!F11:F70,"Virtual",Maestro!BF11:BF70,"finalizado") -> 0 | H29: =COUNTIFS(Maestro!F11:F70,"Virtual",Maestro!BF11:BF70,"en proceso") -> 0 | I29: =COUNTIFS(Maestro!F11:F70,"Virtual",Maestro!BF11:BF70,"sin iniciar") -> 0 | J29: =COUNTIFS(Maestro!F11:F70,"Híbrido",Maestro!BF11:BF70,"finalizado") -> 0 | K29: =COUNTIFS(Maestro!F11:F70,"Híbrido",Maestro!BF11:BF70,"en proceso") -> 0 | L29: =COUNTIFS(Maestro!F11:F70,"Híbrido",Maestro!BF11:BF70,"sin iniciar") -> 0
C30: Banner por modalidad | D30: =COUNTIFS(Maestro!F11:F70,"Presencial",Maestro!BP11:BP70,"finalizado") -> 0 | E30: =COUNTIFS(Maestro!F11:F70,"Presencial",Maestro!BP11:BP70,"en proceso") -> 0 | F30: =COUNTIFS(Maestro!F11:F70,"Presencial",Maestro!BP11:BP70,"sin iniciar") -> 0 | G30: =COUNTIFS(Maestro!F11:F70,"Virtual",Maestro!BP11:BP70,"finalizado") -> 0 | H30: =COUNTIFS(Maestro!F11:F70,"Virtual",Maestro!BP11:BP70,"en proceso") -> 0 | I30: =COUNTIFS(Maestro!F11:F70,"Virtual",Maestro!BP11:BP70,"sin iniciar") -> 1 | J30: =COUNTIFS(Maestro!F11:F70,"Híbrido",Maestro!BP11:BP70,"finalizado") -> 0 | K30: =COUNTIFS(Maestro!F11:F70,"Híbrido",Maestro!BP11:BP70,"en proceso") -> 0 | L30: =COUNTIFS(Maestro!F11:F70,"Híbrido",Maestro!BP11:BP70,"sin iniciar") -> 0
B33: 3. ESTADO POR PROGRAMA — ⏳ X/6 = tiene avance en X etapas ✖ Pendiente = ninguna etapa iniciada (0/6) | N33: ℹ️ La columna SNIES es el identificador único. Todas las etapas se buscan por SNIES con XLOOKUP → el dashboard no se rompe si cambia el orden en la hoja Maestro.
B34: SNIES | C34: Programa | D34: Facultad | E34: Mod. | F34: Plan Virt. | G34: Concepto Fin. | H34: % Avance | I34: Acta Homol. | J34: Aulas Nueva | K34: Banner | L34: Estado
B35: =IF(Maestro!I11="","",Maestro!I11) -> 111231 | C35: =IF(B35="","",_xlfn.LET(_xlpm.v,_xlfn.XLOOKUP(B35,Maestro!$I$11:$I$70,Maestro!$E$11:$E$70,"—"),IF(_xlpm.v="","—",_xlpm.v))) -> — | D35: =IF(B35="","",SUBSTITUTE(_xlfn.XLOOKUP(B35,Maestro!$I$11:$I$70,Maestro!$C$11:$C$70,"—"),"Facultad de ","")) | E35: =IF(B35="","",_xlfn.LET(_xlpm.v,_xlfn.XLOOKUP(B35,Maestro!$I$11:$I$70,Maestro!$F$11:$F$70,"—"),IF(_xlpm.v="","—",_xlpm.v))) -> — | F35: =IF(B35="","",_xlfn.LET(_xlpm.v,_xlfn.XLOOKUP(B35,Maestro!$I$11:$I$70,Maestro!$R$11:$R$70,"—"),IF(_xlpm.v="","—",IF(LEN(_xlpm.v)>1,UPPER(LEFT(_xlpm.v,1))&MID(_xlpm.v,2,LEN(_xlpm.v)),UPPER(_xlpm.v))))) -> — | G35: =IF(B35="","",_xlfn.LET(_xlpm.v,_xlfn.XLOOKUP(B35,Maestro!$I$11:$I$70,Maestro!$U$11:$U$70,"—"),IF(_xlpm.v="","—",IF(LEN(_xlpm.v)>1,UPPER(LEFT(_xlpm.v,1))&MID(_xlpm.v,2,LEN(_xlpm.v)),UPPER(_xlpm.v))))) -> — | H35: =IF(B35="","",_xlfn.LET(_xlpm.v,_xlfn.XLOOKUP(B35,Maestro!$I$11:$I$70,Maestro!$AQ$11:$AQ$70,"—"),IF(ISNUMBER(_xlpm.v),TEXT(_xlpm.v,"0%"),IF(_xlpm.v="","—",IF(LEN(_xlpm.v)>1,UPPER(LEFT(_xlpm.v,1))&MID(_xlpm.v,2,LEN(_xlpm.v)),UPPER(_xlpm.v)))))) -> — | I35: =IF(B35="","",_xlfn.LET(_xlpm.v,_xlfn.XLOOKUP(B35,Maestro!$I$11:$I$70,Maestro!$AR$11:$AR$70,"—"),IF(_xlpm.v="","—",IF(LEN(_xlpm.v)>1,UPPER(LEFT(_xlpm.v,1))&MID(_xlpm.v,2,LEN(_xlpm.v)),UPPER(_xlpm.v))))) -> — | J35: =IF(B35="","",_xlfn.LET(_xlpm.v,_xlfn.XLOOKUP(B35,Maestro!$I$11:$I$70,Maestro!$BD$11:$BD$70,"—"),IF(_xlpm.v="","—",IF(LEN(_xlpm.v)>1,UPPER(LEFT(_xlpm.v,1))&MID(_xlpm.v,2,LEN(_xlpm.v)),UPPER(_xlpm.v))))) -> — | K35: =IF(B35="","",_xlfn.LET(_xlpm.v,_xlfn.XLOOKUP(B35,Maestro!$I$11:$I$70,Maestro!$BP$11:$BP$70,"—"),IF(_xlpm.v="","—",IF(LEN(_xlpm.v)>1,UPPER(LEFT(_xlpm.v,1))&MID(_xlpm.v,2,LEN(_xlpm.v)),UPPER(_xlpm.v))))) -> — | L35: =IF(B35="","",IF(COUNTIF(F35:K35,"Finalizado")=6,"✔ Completo",IF(COUNTIF(F35:K35,"Finalizado")+COUNTIF(F35:K35,"En proceso")=0,"✖ Pendiente","⏳ "&COUNTIF(F35:K35,"Finalizado")&"/6"))) -> ✖ Pendiente
B36: =IF(Maestro!I12="","",Maestro!I12) -> 101647 | C36: =IF(B36="","",_xlfn.LET(_xlpm.v,_xlfn.XLOOKUP(B36,Maestro!$I$11:$I$70,Maestro!$E$11:$E$70,"—"),IF(_xlpm.v="","—",_xlpm.v))) -> — | D36: =IF(B36="","",SUBSTITUTE(_xlfn.XLOOKUP(B36,Maestro!$I$11:$I$70,Maestro!$C$11:$C$70,"—"),"Facultad de ","")) | E36: =IF(B36="","",_xlfn.LET(_xlpm.v,_xlfn.XLOOKUP(B36,Maestro!$I$11:$I$70,Maestro!$F$11:$F$70,"—"),IF(_xlpm.v="","—",_xlpm.v))) -> — | F36: =IF(B36="","",_xlfn.LET(_xlpm.v,_xlfn.XLOOKUP(B36,Maestro!$I$11:$I$70,Maestro!$R$11:$R$70,"—"),IF(_xlpm.v="","—",IF(LEN(_xlpm.v)>1,UPPER(LEFT(_xlpm.v,1))&MID(_xlpm.v,2,LEN(_xlpm.v)),UPPER(_xlpm.v))))) -> — | G36: =IF(B36="","",_xlfn.LET(_xlpm.v,_xlfn.XLOOKUP(B36,Maestro!$I$11:$I$70,Maestro!$U$11:$U$70,"—"),IF(_xlpm.v="","—",IF(LEN(_xlpm.v)>1,UPPER(LEFT(_xlpm.v,1))&MID(_xlpm.v,2,LEN(_xlpm.v)),UPPER(_xlpm.v))))) -> — | H36: =IF(B36="","",_xlfn.LET(_xlpm.v,_xlfn.XLOOKUP(B36,Maestro!$I$11:$I$70,Maestro!$AQ$11:$AQ$70,"—"),IF(ISNUMBER(_xlpm.v),TEXT(_xlpm.v,"0%"),IF(_xlpm.v="","—",IF(LEN(_xlpm.v)>1,UPPER(LEFT(_xlpm.v,1))&MID(_xlpm.v,2,LEN(_xlpm.v)),UPPER(_xlpm.v)))))) -> — | I36: =IF(B36="","",_xlfn.LET(_xlpm.v,_xlfn.XLOOKUP(B36,Maestro!$I$11:$I$70,Maestro!$AR$11:$AR$70,"—"),IF(_xlpm.v="","—",IF(LEN(_xlpm.v)>1,UPPER(LEFT(_xlpm.v,1))&MID(_xlpm.v,2,LEN(_xlpm.v)),UPPER(_xlpm.v))))) -> — | J36: =IF(B36="","",_xlfn.LET(_xlpm.v,_xlfn.XLOOKUP(B36,Maestro!$I$11:$I$70,Maestro!$BD$11:$BD$70,"—"),IF(_xlpm.v="","—",IF(LEN(_xlpm.v)>1,UPPER(LEFT(_xlpm.v,1))&MID(_xlpm.v,2,LEN(_xlpm.v)),UPPER(_xlpm.v))))) -> — | K36: =IF(B36="","",_xlfn.LET(_xlpm.v,_xlfn.XLOOKUP(B36,Maestro!$I$11:$I$70,Maestro!$BP$11:$BP$70,"—"),IF(_xlpm.v="","—",IF(LEN(_xlpm.v)>1,UPPER(LEFT(_xlpm.v,1))&MID(_xlpm.v,2,LEN(_xlpm.v)),UPPER(_xlpm.v))))) -> — | L36: =IF(B36="","",IF(COUNTIF(F36:K36,"Finalizado")=6,"✔ Completo",IF(COUNTIF(F36:K36,"Finalizado")+COUNTIF(F36:K36,"En proceso")=0,"✖ Pendiente","⏳ "&COUNTIF(F36:K36,"Finalizado")&"/6"))) -> ✖ Pendiente
